<?xml version="1.0" ?>
<!-- =================================================================================== -->
<!-- |    This document was autogenerated by xacro from amr.urdf.xacro                 | -->
<!-- |    EDITING THIS FILE BY HAND IS NOT RECOMMENDED                                 | -->
<!-- =================================================================================== -->
<robot name="amr">
  <material name="silver">
    <color rgba="0.7 0.7 0.7 1.0"/>
  </material>
  <link name="base_footprint"/>
  <link name="base_link">
    <visual>
      <origin rpy="0.0 0.0 -1.5707963267948966" xyz="0.0 0.0 0.0"/>
      <geometry>
        <mesh filename="file:///home/naci/dev_ws/install/amr_description/share/amr_description/meshes/base_link.stl" scale="1 1 1"/>
      </geometry>
      <material name="silver"/>
    </visual>
    <collision>
      <origin rpy="0 0 0" xyz="0 0 0"/>
      <geometry>
        <mesh filename="file:///home/naci/dev_ws/install/amr_description/share/amr_description/meshes/base_link.stl" scale="1 1 1"/>
      </geometry>
    </collision>
    <inertial>
      <origin rpy="0.0 0.0 0.0" xyz="0.0 0.0 0.10"/>
      <mass value="118.02415513468259"/>
      <inertia ixx="11.552282" ixy="-0.006658" ixz="0.0" iyy="4.683005" iyz="0.0" izz="15.747905"/>
    </inertial>
  </link>
  <joint name="base_joint" type="fixed">
    <parent link="base_footprint"/>
    <child link="base_link"/>
    <origin rpy="0 0 0" xyz="0 0 0"/>
  </joint>
  <link name="front_left_wheel_link">
    <visual>
      <origin rpy="0.0 0.0 0.0" xyz="0.0 0.0 0.0"/>
      <geometry>
        <mesh filename="file:///home/naci/dev_ws/install/amr_description/share/amr_description/meshes/Mecanum_Left.stl" scale="0.001 0.001 0.001"/>
      </geometry>
      <material name="blue">
        <color rgba="0.1764 0.4588 0.8509 1.0"/>
      </material>
    </visual>
    <collision>
      <origin rpy="1.5707963267948966 0 1.5707963267948966" xyz="0 0 0"/>
      <geometry>
        <cylinder length="0.042" radius="0.08"/>
      </geometry>
    </collision>
    <inertial>
      <origin rpy="0.0 0.0 0.0" xyz="0.0 0.0 0.0"/>
      <mass value="1"/>
      <inertia ixx="0.00256" ixy="0" ixz="0" iyy="0.00256" iyz="0" izz="0.00256"/>
    </inertial>
  </link>
  <joint name="front_left_wheel_joint" type="continuous">
    <axis xyz="0.0 1.0 0.0"/>
    <parent link="base_link"/>
    <child link="front_left_wheel_link"/>
    <origin rpy="0 0 1.5707963267948966" xyz="0.265 0.28 0"/>
  </joint>
  <link name="rear_left_wheel_link">
    <visual>
      <origin rpy="0.0 0.0 0.0" xyz="0.0 0.0 0.0"/>
      <geometry>
        <mesh filename="file:///home/naci/dev_ws/install/amr_description/share/amr_description/meshes/Mecanum_Right.stl" scale="0.001 0.001 0.001"/>
      </geometry>
      <material name="blue">
        <color rgba="0.1764 0.4588 0.8509 1.0"/>
      </material>
    </visual>
    <collision>
      <origin rpy="1.5707963267948966 0 1.5707963267948966" xyz="0 0 0"/>
      <geometry>
        <cylinder length="0.042" radius="0.08"/>
      </geometry>
    </collision>
    <inertial>
      <origin rpy="0.0 0.0 0.0" xyz="0.0 0.0 0.0"/>
      <mass value="1"/>
      <inertia ixx="0.00256" ixy="0" ixz="0" iyy="0.00256" iyz="0" izz="0.00256"/>
    </inertial>
  </link>
  <joint name="rear_left_wheel_joint" type="continuous">
    <axis xyz="0.0 1.0 0.0"/>
    <parent link="base_link"/>
    <child link="rear_left_wheel_link"/>
    <origin rpy="0 0 1.5707963267948966" xyz="-0.265 0.28 0"/>
  </joint>
  <link name="front_right_wheel_link">
    <visual>
      <origin rpy="0.0 0.0 0.0" xyz="0.0 0.0 0.0"/>
      <geometry>
        <mesh filename="file:///home/naci/dev_ws/install/amr_description/share/amr_description/meshes/Mecanum_Right.stl" scale="0.001 0.001 0.001"/>
      </geometry>
      <material name="blue">
        <color rgba="0.1764 0.4588 0.8509 1.0"/>
      </material>
    </visual>
    <collision>
      <origin rpy="1.5707963267948966 0 1.5707963267948966" xyz="0 0 0"/>
      <geometry>
        <cylinder length="0.042" radius="0.08"/>
      </geometry>
    </collision>
    <inertial>
      <origin rpy="0.0 0.0 0.0" xyz="0.0 0.0 0.0"/>
      <mass value="1"/>
      <inertia ixx="0.00256" ixy="0" ixz="0" iyy="0.00256" iyz="0" izz="0.00256"/>
    </inertial>
  </link>
  <joint name="front_right_wheel_joint" type="continuous">
    <axis xyz="0.0 1.0 0.0"/>
    <parent link="base_link"/>
    <child link="front_right_wheel_link"/>
    <origin rpy="0 0 1.5707963267948966" xyz="0.265 -0.28 0"/>
  </joint>
  <link name="rear_right_wheel_link">
    <visual>
      <origin rpy="0.0 0.0 0.0" xyz="0.0 0.0 0.0"/>
      <geometry>
        <mesh filename="file:///home/naci/dev_ws/install/amr_description/share/amr_description/meshes/Mecanum_Left.stl" scale="0.001 0.001 0.001"/>
      </geometry>
      <material name="blue">
        <color rgba="0.1764 0.4588 0.8509 1.0"/>
      </material>
    </visual>
    <collision>
      <origin rpy="1.5707963267948966 0 1.5707963267948966" xyz="0 0 0"/>
      <geometry>
        <cylinder length="0.042" radius="0.08"/>
      </geometry>
    </collision>
    <inertial>
      <origin rpy="0.0 0.0 0.0" xyz="0.0 0.0 0.0"/>
      <mass value="1"/>
      <inertia ixx="0.00256" ixy="0" ixz="0" iyy="0.00256" iyz="0" izz="0.00256"/>
    </inertial>
  </link>
  <joint name="rear_right_wheel_joint" type="continuous">
    <axis xyz="0.0 1.0 0.0"/>
    <parent link="base_link"/>
    <child link="rear_right_wheel_link"/>
    <origin rpy="0 0 1.5707963267948966" xyz="-0.265 -0.28 0"/>
  </joint>
  <link name="lidar_link">
    <visual>
      <origin rpy="0.0 0.0 0.0" xyz="0.0 0.0 0.0"/>
      <geometry>
        <mesh filename="file:///home/naci/dev_ws/install/amr_description/share/amr_description/meshes/rpi_lidar_1.stl" scale="1 1 1"/>
      </geometry>
      <material name="black">
        <color rgba="0 0 0 1.0"/>
      </material>
    </visual>
    <collision>
      <origin rpy="0.0 0.0 0.0" xyz="0.0 0.0 0.0"/>
      <geometry>
        <mesh filename="file:///home/naci/dev_ws/install/amr_description/share/amr_description/meshes/rpi_lidar_1.stl" scale="1 1 1"/>
      </geometry>
    </collision>
    <inertial>
      <origin rpy="0 0 0" xyz="0 0 0"/>
      <mass value="0.1"/>
      <inertia ixx="5.625000000000001e-05" ixy="0" ixz="0" iyy="5.625000000000001e-05" iyz="0" izz="5.625000000000001e-05"/>
    </inertial>
  </link>
  <joint name="lidar_joint" type="fixed">
    <parent link="base_link"/>
    <child link="lidar_link"/>
    <origin rpy="0 0 0" xyz="0.0 0.0 0.125"/>
  </joint>
</robot>
